Workbook

Sheet 封面
B2: 数据要素概念深度清洗报告
B3: 复核日期：2026-10-27｜范围：原98只候选｜口径：核心/相关保留，边缘/错标退出，物理AI单列
B6: 原候选股数（只） | C6: =COUNTA('清洗总表'!$B$5:$B$102)
B7: 保留数据要素（只） | C7: =COUNTA('保留股池'!$B$5:$B$81)
B8: 其中：核心（只） | C8: =COUNTIF('保留股池'!$H$5:$H$81,"核心")
B9: 其中：相关（只） | C9: =COUNTIF('保留股池'!$H$5:$H$81,"相关")
B10: 迁回物理AI（只） | C10: =COUNTIF('摘除与迁出'!$F$5:$F$25,"物理AI")
B11: 完全摘除（只） | C11: =COUNTIF('摘除与迁出'!$E$5:$E$25,"摘除")
B14: 工作表索引
B15: 清洗总表 | C15: 98只全量旧概念、新概念、判词、详细理由及证据
B16: 保留股池 | C16: 清洗后77只核心/相关标的
B17: 摘除与迁出 | C17: 14只摘除及7只物理AI迁移的审计理由
B18: 数据存储复核 | C18: 截图原15只的专项纠正
B19: 概念统计 | C19: 保留股池二级概念的核心/相关数量
B22: 判定口径：核心=该数据产品/服务是明确主要产品；相关=有真实产品或项目但主要仍为信息化、云、硬件或项目交付。
B23: 退出口径：边缘=少量参股、自用数据或上游感知设备；错标=无直接证据、业务已失效或二级概念明显不符。
B24: 主营资料：iFinD ifind_get_stock_info（2026-10-27）；概念证据：逐股年报、公告、公司官网或互动平台，详见Source列。

Sheet 清洗总表
B2: 数据要素概念深度清洗 · 全量明细
B3: 98 只逐项复核；理由与二级概念同步重写，证据可点击或复制访问。
B4: 代码 | C4: 名称 | D4: 旧概念 | E4: 动作 | F4: 新一级分类 | G4: 新概念 | H4: 判词 | I4: 详细理由 | J4: 证据名称 | K4: 证据日期 | L4: Source Name | M4: Source URL
B5: 000032 | C5: 深桑达A | D5: 数据要素_数据存储 | E5: 重分类 | F5: 数据要素 | G5: 数据要素_数据运营 | H5: 核心 | I5: 中国电子云数据港对接获授权的公共数据与社会数据，开展治理、融合和产品孵化，并以“蚝保宝”等数据产品面向企业及交易所输出。业务重点是持续运营和数据产品服务，而非单纯提供存储资源。 | J5: 深桑达A 2024年年度报告摘要 | K5: 2025-04-25 | L5: iFinD ifind_get_stock_info (as of 2026-10-27)；深桑达A 2024年年度报告摘要 | M5: https://static.cninfo.com.cn/finalpage/2025-04-25/1223281534.PDF
B6: 000156 | C6: 华数传媒 | D6: 物理AI_数据采集 | E6: 摘除 | H6: 错标 | I6: 主业为有线电视、新媒体、宽带、智慧城市数字化及广电5G，收入来自节目传输、网络接入和数字化项目。数据要素仅是未来投资方向，未核到独立数据产品，更不属于物理AI数据采集。 | J6: 华数传媒2025年年度报告 | K6: 2026-03-21 | L6: iFinD ifind_get_stock_info (as of 2026-10-27)；华数传媒2025年年度报告 | M6: https://money.finance.sina.com.cn/corp/view/vCB_AllBulletinDetail.php?stockid=000156&id=12009319
B7: 000158 | C7: 常山北明 | D7: 数据要素_数据存储 | E7: 重分类 | F7: 数据要素 | G7: 数据要素_数据治理 | H7: 相关 | I7: 北明软件具备数据资源化、产品化、资产化、资本化流程服务，配有数据资产管理平台，并在交通、港口及企业场景开展统一治理。收入仍主要来自系统集成、行业解决方案和定制软件，不属于底层存储产品。 | J7: 常山北明2025年年度报告 | K7: 2026-04-03 | L7: iFinD ifind_get_stock_info (as of 2026-10-27)；常山北明2025年年度报告 | M7: http://money.finance.sina.com.cn/corp/view/vCB_AllBulletinDetail.php?stockid=000158&id=12060253
B8: 000503 | C8: 国新健康 | D8: 数据要素_医疗数据 | E8: 保留 | F8: 数据要素 | G8: 数据要素_医疗数据 | H8: 核心 | I8: 公司面向医保部门提供数据应用第三方服务并维护国家医保编码库，同时将商保核保、核赔数据产品上架流通。收费和交付围绕医保、医疗数据治理及场景化应用展开，数据资源与产品形态均明确。 | J8: 国新健康2025年年度报告 | K8: 2026-04-29 | L8: iFinD ifind_get_stock_info (as of 2026-10-27)；国新健康2025年年度报告 | M8: https://money.finance.sina.com.cn/corp/view/vCB_AllBulletinDetail.php?stockid=000503&id=12247512
B9: 000681 | C9: 视觉中国 | D9: 数据要素_图片数据 | E9: 保留 | F9: 数据要素 | G9: 数据要素_图片数据 | H9: 核心 | I9: 公司拥有合规图片及多模态训练数据，提供采集、标注、审核、认证及授权服务，并通过API、沙箱等方式交付和参与分成。图片及多模态内容经过加工后形成可授权的数据产品，业务链条完整。 | J9: 视觉中国2025年半年度报告 | K9: 2025-08-28 | L9: iFinD ifind_get_stock_info (as of 2026-10-27)；视觉中国2025年半年度报告 | M9: http://static.cninfo.com.cn/finalpage/2025-08-28/1224596966.PDF
B10: 000719 | C10: 中原传媒 | D10: 数据要素_交易所 | E10: 摘除 | H10: 边缘 | I10: 公司仅出资参股郑州数据交易中心，主营业务仍为出版、发行及相关文化服务。现有证据体现的是财务投资，而非上市公司直接建设或运营数据交易平台，严格口径下不参与数据要素选股。 | J10: 中原传媒参股郑州数据交易中心相关说明 | K10: 2024-11-18 | L10: iFinD ifind_get_stock_info (as of 2026-10-27)；中原传媒参股郑州数据交易中心相关说明 | M10: https://yuanchuang.10jqka.com.cn/20241118/c663606520.shtml
B11: 000810 | C11: 创维数字 | D11: 物理AI_数据采集 | E11: 迁出数据要素 | F11: 物理AI | G11: 物理AI_智能终端 | H11: 相关 | I11: 机顶盒、宽带连接终端、XR设备及摄像机属于智能终端硬件，现有主营资料未显示其对外提供数据采集、加工或数据集服务。应保留在物理AI终端链，而不是数据要素或数据采集概念。 | J11: 创维数字2025年年度报告摘要 | K11: 2026-03-28 | L11: iFinD ifind_get_stock_info (as of 2026-10-27)；创维数字2025年年度报告摘要 | M11: http://static.cninfo.com.cn/finalpage/2026-03-28/1225044554.PDF
B12: 000815 | C12: 美利云 | D12: 数据要素_数据存储 | E12: 升级 | F12: 数据要素 | G12: 数据要素_数据存储 | H12: 相关 | I12: 公司已于2024年底停止造纸，旧“造纸为主”理由失效；誉成云创目前提供机架、网络接入及运维并按合同收费，云业务已成为主体。其本质仍是IDC基础设施服务，而非数据内容运营，故列相关而非核心。 | J12: 美利云2025年年度报告 | K12: 2026-04-24 | L12: iFinD ifind_get_stock_info (as of 2026-10-27)；美利云2025年年度报告 | M12: http://static.cninfo.com.cn/finalpage/2026-04-24/1225160605.PDF
B13: 000938 | C13: 紫光股份 | D13: 数据要素_数据存储 | E13: 保留 | F13: 数据要素 | G13: 数据要素_数据存储 | H13: 相关 | I13: 新华三ONEStor、UniStor等产品处理块、文件、对象及非结构化数据，通过软硬件、软件授权和解决方案交付。产品确属数据存储基础设施，但上市公司业务还覆盖网络、计算及云服务，因此维持相关。 | J13: H3C ONEStor分布式存储软件 | K13: 无日期 | L13: iFinD ifind_get_stock_info (as of 2026-10-27)；H3C ONEStor分布式存储软件 | M13: https://www.h3c.com/cn/Products_And_Solution/Storage/H3C/Products/Mass_Storage_Device/Products_Series/Software/ONEStor_5.0/
B14: 000948 | C14: 南天信息 | D14: 数据要素_数据存储 | E14: 重分类 | F14: 数据要素 | G14: 数据要素_数据治理 | H14: 相关 | I14: 南天数据资产管理平台覆盖数据集成、治理、目录、盘点和运营，主要面向金融客户以IT项目方式交付。其价值在于把分散数据加工为可管理、可使用的资产，而非提供底层存储介质。 | J14: 南天数据资产管理平台 | K14: 2024-07-30 | L14: iFinD ifind_get_stock_info (as of 2026-10-27)；南天数据资产管理平台 | M14: https://www.nantian.com.cn/case-detail/2375.html
B15: 002009 | C15: 天奇股份 | D15: 物理AI_数据采集 | E15: 迁出数据要素 | F15: 物理AI | G15: 物理AI_数据采集 | H15: 相关 | I15: 具身智能业务及实训中心采集多模态真机数据，用于机器人训练和交付验证，相关能力随装备、实训及解决方案项目落地。该标签适用于物理AI训练链，不应混入数据要素股池。 | J15: 天奇股份2025年年度报告摘要 | K15: 2026-04-28 | L15: iFinD ifind_get_stock_info (as of 2026-10-27)；天奇股份2025年年度报告摘要 | M15: https://static.cninfo.com.cn/finalpage/2026-04-28/1225218333.PDF
B16: 002065 | C16: 东华软件 | D16: 数据要素_交易所 | E16: 重分类 | F16: 数据要素 | G16: 数据要素_数据治理 | H16: 相关 | I16: 年报列明大数据平台、数据交易所及金融数据资产管理平台建设；“替代数据通”整合公积金、社保、税务、司法和工商数据。主要是软件、集成和项目交付，不能据此认定为交易所运营方。 | J16: 东华软件2025年年度报告 | K16: 2026-04-10 | L16: iFinD ifind_get_stock_info (as of 2026-10-27)；东华软件2025年年度报告 | M16: http://static.cninfo.com.cn/finalpage/2026-04-10/1225090051.PDF
B17: 002076 | C17: 星光股份 | D17: 数据要素_其他行业数据 | E17: 摘除 | H17: 错标 | I17: 公司拟收购“造价通”事项已于2025年6月终止，相关合资公司亦未实缴，不能把造价通建材价格库计入上市公司。现有主营与独立行业数据产品之间缺少可核验的承接关系。 | J17: 星光股份终止收购相关公告及2025年半年度报告 | K17: 2025-08-30 | L17: iFinD ifind_get_stock_info (as of 2026-10-27)；星光股份终止收购相关公告及2025年半年度报告 | M17: https://money.finance.sina.com.cn/corp/view/vCB_AllBulletinDetail.php?stockid=002076&id=11423604
B18: 002095 | C18: 生意宝 | D18: 数据要素_大宗数据 | E18: 升级 | F18: 数据要素 | G18: 数据要素_大宗数据 | H18: 核心 | I18: 生意社持续加工大宗商品价格数据，形成多品种基准价，并通过期货通订阅及价格、指数API提供服务。数据来源、加工过程、产品形态和订阅或接口交付方式均明确，大宗数据是直接产品。 | J18: 生意社接口服务 | K18: 2019-02-22 | L18: iFinD ifind_get_stock_info (as of 2026-10-27)；生意社接口服务 | M18: https://www.100ppi.com/help/service/api.html
B19: 002152 | C19: 广电运通 | D19: 数据要素_数据存储 | E19: 重分类 | F19: 数据要素 | G19: 数据要素_数据运营 | H19: 相关 | I19: 运通信息、清远数投参与公共数据运营，“清易贷”“清易保”等产品已上架，中数智汇拥有产业链及ESG数据集。业务覆盖数据治理、产品开发和场景运营，但上市公司仍包含大量智能终端业务。 | J19: 广电运通公共数据运营业务说明 | K19: 2025-08-01 | L19: iFinD ifind_get_stock_info (as of 2026-10-27)；广电运通公共数据运营业务说明 | M19: https://www.grgbanking.com/cn/news/detail.html?id=2308
B20: 002153 | C20: 石基信息 | D20: 数据要素_酒店数据 | E20: 保留 | F20: 数据要素 | G20: 数据要素_酒店数据 | H20: 相关 | I20: DAYLIGHT PMS、Cambridge等系统处理酒店订单、餐饮和经营数据，并以SaaS订阅方式收费。公司持续处理行业数据，但主要销售酒店信息系统及订阅服务，而非独立数据库或数据产品。 | J20: 石基信息2024年年度报告摘要 | K20: 2025-04-29 | L20: iFinD ifind_get_stock_info (as of 2026-10-27)；石基信息2024年年度报告摘要 | M20: https://static.cninfo.com.cn/finalpage/2025-04-29/1223378885.PDF
B21: 002235 | C21: 安妮股份 | D21: 数据要素_数据确权 | E21: 升级 | F21: 数据要素 | G21: 数据要素_数据确权 | H21: 核心 | I21: “版权家”提供确权、授权、维权、信息及资产管理，以区块链完成数字版权存证并记录授权全过程，具备明确的数据确权产品链条。版权业务收入占比有限，但产品与数据确权标签高度匹配。 | J21: 安妮股份2025年年度报告 | K21: 2026-04-28 | L21: iFinD ifind_get_stock_info (as of 2026-10-27)；安妮股份2025年年度报告 | M21: https://money.finance.sina.com.cn/corp/view/vCB_AllBulletinDetail.php?stockid=002235&id=12229256
B22: 002238 | C22: 天威视讯 | D22: 数据要素_网络可视化监管 | E22: 重分类 | F22: 数据要素 | G22: 数据要素_数据存储 | H22: 相关 | I22: 未找到公司从事网络可视化监管的可靠证据；其深汕、南山、龙华数据中心提供机柜托管、服务器及网络资源租用，更符合数据存储基础设施。上市公司主业仍包含有线电视，故列相关。 | J22: 天威视讯2025年年度报告 | K22: 2026-04-22 | L22: iFinD ifind_get_stock_info (as of 2026-10-27)；天威视讯2025年年度报告 | M22: https://static.cninfo.com.cn/finalpage/2026-04-22/1225142912.PDF
B23: 002331 | C23: 皖通科技 | D23: 数据要素_交通数据 | E23: 保留 | F23: 数据要素 | G23: 数据要素_交通数据 | H23: 相关 | I23: 港航云、CiTOS和交通数据中台汇聚车流、闸口、堆场及物流订单数据，用于港航和交通管理场景。相关能力主要随软硬件、系统集成和运维项目交付，尚未体现独立数据销售成为主体。 | J23: 皖通科技：以数据要素激活交通发展新势能 | K23: 无可靠日期 | L23: iFinD ifind_get_stock_info (as of 2026-10-27)；皖通科技：以数据要素激活交通发展新势能 | M23: http://www.wantong-tech.net/detail/21_2165
B24: 002354 | C24: 天娱数科 | D24: 物理AI_数据采集 | E24: 迁出数据要素 | F24: 物理AI | G24: 物理AI_数据采集 | H24: 相关 | I24: Behavision形成3D、多模态和机器人任务数据，并通过空间智能MaaS、数据集服务等方式交付，直接服务于机器人及物理AI训练。业务与物理AI相关，但不应与数据要素公共数据流通混为一组。 | J24: 天娱数科物理AI数据业务说明 | K24: 2025-07-28 | L24: iFinD ifind_get_stock_info (as of 2026-10-27)；天娱数科物理AI数据业务说明 | M24: https://www.tianyushuke.com/xwmt/2025/2025-07-28/907.html
B25: 002368 | C25: 太极股份 | D25: 数据要素_数据存储 | E25: 重分类 | F25: 数据要素 | G25: 数据要素_数据库 | H25: 相关 | I25: 电科金仓KingbaseES、KES及分布式HTAP数据库通过许可、一体机和项目方式交付，承担数据组织、查询、事务处理和管理功能。产品层级是数据库软件，不等同于通用存储设备。 | J25: 太极股份2024年年度报告 | K25: 2025-04-02 | L25: iFinD ifind_get_stock_info (as of 2026-10-27)；太极股份2024年年度报告 | M25: https://money.finance.sina.com.cn/corp/view/vCB_AllBulletinDetail.php?stockid=002368&id=10840405
B26: 002373 | C26: 千方科技 | D26: 数据要素_交通数据 | E26: 保留 | F26: 数据要素 | G26: 数据要素_交通数据 | H26: 相关 | I26: 交通大数据中台及全国公路网平台汇聚视频、收费、位置、货运和气象数据，以产品结合数据运营及TOCC项目交付。公司具有明确交通数据资源和应用能力，但交付仍与系统建设深度融合。 | J26: 千方科技参加2023数据资产管理大会 | K26: 2023-12-21 | L26: iFinD ifind_get_stock_info (as of 2026-10-27)；千方科技参加2023数据资产管理大会 | M26: https://www.ctfo.com/newsDetails?id=1852
B27: 002380 | C27: 科远智慧 | D27: 物理AI_数据采集 | E27: 迁出数据要素 | F27: 物理AI | G27: 物理AI_数据采集 | H27: 相关 | I27: NT6000 DCS、SyncBASE实时数据库和EmpoworX平台采集设备、工艺及质量数据，并随工控、MES、工业互联网项目交付。其采集对象主要是工业生产过程，适合物理AI工业数据链，不并入数据要素。 | J27: 科远智慧公司及产品体系介绍 | K27: 2018-08-08 | L27: iFinD ifind_get_stock_info (as of 2026-10-27)；科远智慧公司及产品体系介绍 | M27: https://www.sciyon.com/index.php/about/info.html
B28: 002401 | C28: 中远海科 | D28: 数据要素_航运数据 | E28: 升级 | F28: 数据要素 | G28: 数据要素_航运数据 | H28: 核心 | I28: “船视宝”以SaaS、API和半定制方式交付，并在上海数交所等挂牌；全要素航运数据集已形成规模化产品。数字航运与供应链是主要业务板块，数据产品、收费方式和业务占比均有支撑。 | J28: 中远海科2025年年度报告 | K28: 2026-03-28 | L28: iFinD ifind_get_stock_info (as of 2026-10-27)；中远海科2025年年度报告 | M28: http://money.finance.sina.com.cn/corp/view/vCB_AllBulletinDetail.php?stockid=002401&id=12027926
B29: 002410 | C29: 广联达 | D29: 数据要素_其他行业数据 | E29: 保留 | F29: 数据要素 | G29: 数据要素_其他行业数据 | H29: 核心 | I29: 广材网、广材助手提供信息价、市场价、采购建议价及人工询价，指标网提供成本、清单和劳务数据，并与计价软件打通。建筑造价数据经持续加工形成订阅及软件数据服务。 | J29: 广联达广材数据服务 | K29: 2025-08-27 | L29: iFinD ifind_get_stock_info (as of 2026-10-27)；广联达广材数据服务 | M29: https://www.glodon.com/product/209.html
... B33: 002777 | C33: 久远银海 | D33: 数据要素_医疗数据 | E33: 保留 | F33: 数据要素 | G33: 数据要素_医疗数据 | H33: 相关 | I33: 诚信宝、医商通、信用就医及津医保处理医保、医疗和人社数据，以软件、运维和联合运营交付，贵州子公司提供商保结算等服务。数据产品已落地但收入仍归入软件运维。 | J33: 久远银海2025年年度报告 | K33: 2026-03-27 | L33: iFinD ifind_get_stock_info (as of 2026-10-27)；久远银海2025年年度报告 | M33: https://money.finance.sina.com.cn/corp/view/vCB_AllBulletinDetail.php?stockid=002777&id=12020502
B34: 002869 | C34: 金溢科技 | D34: 数据要素_交通数据 | E34: 摘除 | H34: 边缘 | I34: OBU、RSU、RFID及全息路口采集车辆身份、收费和路况数据，主要以智能终端、路侧设备及边端系统项目销售。未核到独立交通数据产品收费，属于上游感知和项目交付，严格口径下移出数据要素。 | J34: 金溢科技2024年年度报告 | K34: 2025-04-22 | L34: iFinD ifind_get_stock_info (as of 2026-10-27)；金溢科技2024年年度报告 | M34: http://money.finance.sina.com.cn/corp/view/vCB_AllBulletinDetail.php?stockid=002869&id=10921058
B35: 002908 | C35: 德生科技 | D35: 数据要素_其他行业数据 | E35: 升级 | F35: 数据要素 | G35: 数据要素_其他行业数据 | H35: 核心 | I35: 全口径劳动力平台、就业分析及政务核验产品处理授权人社和就业数据，通过就业运营、数据专区运维及服务合同收费。人社运营及大数据服务已是明确主要产品，数据服务并非单纯内部自用。 | J35: 德生科技2025年年度报告 | K35: 2026-04-25 | L35: iFinD ifind_get_stock_info (as of 2026-10-27)；德生科技2025年年度报告 | M35: https://money.finance.sina.com.cn/corp/view/vCB_AllBulletinDetail.php?stockid=002908&id=12189979
B36: 002912 | C36: 中新赛克 | D36: 数据要素_网络可视化监管 | E36: 保留 | F36: 数据要素 | G36: 数据要素_网络可视化监管 | H36: 相关 | I36: 宽带网、移动网产品提取网络流量，DFP、AIP及数据融合平台做多模态研判，以软硬件、安装调试和培训交付。主体仍是网络可视化监管设备和方案，数据运营产品占比较小。 | J36: 中新赛克2025年年度报告 | K36: 2026-03-18 | L36: iFinD ifind_get_stock_info (as of 2026-10-27)；中新赛克2025年年度报告 | M36: https://money.finance.sina.com.cn/corp/view/vCB_AllBulletinDetail.php?stockid=002912&id=12001026
B37: 003005 | C37: 竞业达 | D37: 数据要素_其他行业数据 | E37: 重分类 | F37: 数据要素 | G37: 数据要素_教育数据 | H37: 相关 | I37: 星云产业需求数据库、课堂质量诊断和AIGC服务处理教学、考务数据，以教育信息化方案、产品和订阅交付。安全中台仅提供招考视频、证书和密钥安全，不是独立数据安全产品。 | J37: 竞业达2025年年度报告摘要 | K37: 2026-04-29 | L37: iFinD ifind_get_stock_info (as of 2026-10-27)；竞业达2025年年度报告摘要 | M37: https://disc.static.szse.cn/download/disc/disk03/finalpage/2026-04-29/19917dfc-97c1-477c-a9f1-85880ace76cc.PDF
B38: 300085 | C38: 银之杰 | D38: 数据要素_其他行业数据 | E38: 摘除 | H38: 边缘 | I38: 金融软件、数据中台为银行处理业务数据并按软件和设备交付，征信逻辑主要来自联营及参股机构。上市公司自身未见独立征信数据主产品，且其他业务占比较大，严格口径下不再纳入数据要素。 | J38: 银之杰2025年年度报告 | K38: 2026-04-15 | L38: iFinD ifind_get_stock_info (as of 2026-10-27)；银之杰2025年年度报告 | M38: https://money.finance.sina.com.cn/corp/view/vCB_AllBulletinDetail.php?stockid=300085&id=12089901
B39: 300166 | C39: 东方国信 | D39: 数据要素_数据清洗 | E39: 降级 | F39: 数据要素 | G39: 数据要素_数据清洗 | H39: 相关 | I39: CirroData、BELAKE及“早安老板”处理企业、标讯数据的采集、清洗、标注和检索，以定制软件、系统集成和软件产品交付。数据清洗并非独立主产品，且公司明确称未与北数所合作，交易所映射删除。 | J39: 东方国信2025年年度报告及互动平台答复 | K39: 2026-04-24 | L39: iFinD ifind_get_stock_info (as of 2026-10-27)；东方国信2025年年度报告及互动平台答复 | M39: https://money.finance.sina.com.cn/corp/view/vCB_AllBulletinDetail.php?stockid=300166&id=12175116
B40: 300168 | C40: 万达信息 | D40: 数据要素_交易所 | E40: 重分类 | F40: 数据要素 | G40: 数据要素_医疗数据 | H40: 相关 | I40: OMOP糖尿病模型评估、“灵素”体检解读和宁波医疗流通平台处理医疗健康数据，以软件开发、运维、授权运营及挂牌产品交付。公司是上数所第三方服务商而非交易所运营方。 | J40: 万达信息2025年年度报告 | K40: 2026-04-29 | L40: iFinD ifind_get_stock_info (as of 2026-10-27)；万达信息2025年年度报告 | M40: http://file.finance.sina.com.cn/211.154.219.97:9494/MRGG/CNSESZ_STOCK/2026/2026-4/2026-04-29/12242514.PDF
B41: 300226 | C41: 上海钢联 | D41: 数据要素_大宗数据 | E41: 保留 | F41: 数据要素 | G41: 数据要素_大宗数据 | H41: 核心 | I41: Mysteel、钢联数据终端和隆众资讯持续采集钢铁、能源等价格、库存及供需数据，通过数据订阅、数据接口、研究咨询收费。客户购买对象就是持续更新的商品数据和研究成果。 | J41: 上海钢联2025年年度报告 | K41: 2026-04-28 | L41: iFinD ifind_get_stock_info (as of 2026-10-27)；上海钢联2025年年度报告 | M41: http://money.finance.sina.com.cn/corp/view/vCB_AllBulletinDetail.php?stockid=300226&id=12225019
B42: 300250 | C42: 初灵信息 | D42: 数据要素_数据分析 | E42: 保留 | F42: 数据要素 | G42: 数据要素_数据分析 | H42: 相关 | I42: DPI数据感知系统、EDPP平台采集解析运营商网络流量，并提供故障定位、视频用户行为分析，主要通过招标销售系统和扩容升级服务。交付的是分析平台而非独立数据库。 | J42: 初灵信息2025年年度报告 | K42: 2026-04-27 | L42: iFinD ifind_get_stock_info (as of 2026-10-27)；初灵信息2025年年度报告 | M42: https://money.finance.sina.com.cn/corp/view/vCB_AllBulletinDetail.php?stockid=300250&id=12205319
B43: 300271 | C43: 华宇软件 | D43: 数据要素_司法数据 | E43: 保留 | F43: 数据要素 | G43: 数据要素_司法数据 | H43: 相关 | I43: 法律高质量数据集、万象问数处理裁判文书、法规和检察业务数据，以法律大模型、应用软件、系统建设及运维交付。数据主要支撑自有AI和客户办案，未见独立司法数据订阅成为主产品。 | J43: 华宇软件2025年年度报告 | K43: 2026-04-28 | L43: iFinD ifind_get_stock_info (as of 2026-10-27)；华宇软件2025年年度报告 | M43: https://static.cninfo.com.cn/finalpage/2026-04-28/1225213050.PDF
B44: 300287 | C44: 飞利信 | D44: 数据要素_数据清洗 | E44: 保留 | F44: 数据要素 | G44: 数据要素_数据清洗 | H44: 相关 | I44: 诺玛大数据平台、KingMap和可信数据空间整合电网、政务及时空数据，提供治理、分析和跨域协同，按数据软件及项目交付。数据软件是业务板块之一，但清洗并非独立数据商品。 | J44: 飞利信2025年半年度报告 | K44: 2025-08-29 | L44: iFinD ifind_get_stock_info (as of 2026-10-27)；飞利信2025年半年度报告 | M44: https://money.finance.sina.com.cn/corp/view/vCB_AllBulletinDetail.php?stockid=300287&id=11412326
...

Sheet 保留股池
B2: 数据要素 · 严格口径保留股池
B3: 仅保留核心与相关标的；二级概念已按实际产品、平台和交付方式重新归类。
B4: 代码 | C4: 名称 | D4: 旧概念 | E4: 动作 | F4: 新一级分类 | G4: 新概念 | H4: 判词 | I4: 详细理由 | J4: 证据名称 | K4: 证据日期 | L4: Source Name | M4: Source URL
B5: 000032 | C5: 深桑达A | D5: 数据要素_数据存储 | E5: 重分类 | F5: 数据要素 | G5: 数据要素_数据运营 | H5: 核心 | I5: 中国电子云数据港对接获授权的公共数据与社会数据，开展治理、融合和产品孵化，并以“蚝保宝”等数据产品面向企业及交易所输出。业务重点是持续运营和数据产品服务，而非单纯提供存储资源。 | J5: 深桑达A 2024年年度报告摘要 | K5: 2025-04-25 | L5: iFinD ifind_get_stock_info (as of 2026-10-27)；深桑达A 2024年年度报告摘要 | M5: https://static.cninfo.com.cn/finalpage/2025-04-25/1223281534.PDF
B6: 000158 | C6: 常山北明 | D6: 数据要素_数据存储 | E6: 重分类 | F6: 数据要素 | G6: 数据要素_数据治理 | H6: 相关 | I6: 北明软件具备数据资源化、产品化、资产化、资本化流程服务，配有数据资产管理平台，并在交通、港口及企业场景开展统一治理。收入仍主要来自系统集成、行业解决方案和定制软件，不属于底层存储产品。 | J6: 常山北明2025年年度报告 | K6: 2026-04-03 | L6: iFinD ifind_get_stock_info (as of 2026-10-27)；常山北明2025年年度报告 | M6: http://money.finance.sina.com.cn/corp/view/vCB_AllBulletinDetail.php?stockid=000158&id=12060253
B7: 000503 | C7: 国新健康 | D7: 数据要素_医疗数据 | E7: 保留 | F7: 数据要素 | G7: 数据要素_医疗数据 | H7: 核心 | I7: 公司面向医保部门提供数据应用第三方服务并维护国家医保编码库，同时将商保核保、核赔数据产品上架流通。收费和交付围绕医保、医疗数据治理及场景化应用展开，数据资源与产品形态均明确。 | J7: 国新健康2025年年度报告 | K7: 2026-04-29 | L7: iFinD ifind_get_stock_info (as of 2026-10-27)；国新健康2025年年度报告 | M7: https://money.finance.sina.com.cn/corp/view/vCB_AllBulletinDetail.php?stockid=000503&id=12247512
B8: 000681 | C8: 视觉中国 | D8: 数据要素_图片数据 | E8: 保留 | F8: 数据要素 | G8: 数据要素_图片数据 | H8: 核心 | I8: 公司拥有合规图片及多模态训练数据，提供采集、标注、审核、认证及授权服务，并通过API、沙箱等方式交付和参与分成。图片及多模态内容经过加工后形成可授权的数据产品，业务链条完整。 | J8: 视觉中国2025年半年度报告 | K8: 2025-08-28 | L8: iFinD ifind_get_stock_info (as of 2026-10-27)；视觉中国2025年半年度报告 | M8: http://static.cninfo.com.cn/finalpage/2025-08-28/1224596966.PDF
B9: 000815 | C9: 美利云 | D9: 数据要素_数据存储 | E9: 升级 | F9: 数据要素 | G9: 数据要素_数据存储 | H9: 相关 | I9: 公司已于2024年底停止造纸，旧“造纸为主”理由失效；誉成云创目前提供机架、网络接入及运维并按合同收费，云业务已成为主体。其本质仍是IDC基础设施服务，而非数据内容运营，故列相关而非核心。 | J9: 美利云2025年年度报告 | K9: 2026-04-24 | L9: iFinD ifind_get_stock_info (as of 2026-10-27)；美利云2025年年度报告 | M9: http://static.cninfo.com.cn/finalpage/2026-04-24/1225160605.PDF
B10: 000938 | C10: 紫光股份 | D10: 数据要素_数据存储 | E10: 保留 | F10: 数据要素 | G10: 数据要素_数据存储 | H10: 相关 | I10: 新华三ONEStor、UniStor等产品处理块、文件、对象及非结构化数据，通过软硬件、软件授权和解决方案交付。产品确属数据存储基础设施，但上市公司业务还覆盖网络、计算及云服务，因此维持相关。 | J10: H3C ONEStor分布式存储软件 | K10: 无日期 | L10: iFinD ifind_get_stock_info (as of 2026-10-27)；H3C ONEStor分布式存储软件 | M10: https://www.h3c.com/cn/Products_And_Solution/Storage/H3C/Products/Mass_Storage_Device/Products_Series/Software/ONEStor_5.0/
B11: 000948 | C11: 南天信息 | D11: 数据要素_数据存储 | E11: 重分类 | F11: 数据要素 | G11: 数据要素_数据治理 | H11: 相关 | I11: 南天数据资产管理平台覆盖数据集成、治理、目录、盘点和运营，主要面向金融客户以IT项目方式交付。其价值在于把分散数据加工为可管理、可使用的资产，而非提供底层存储介质。 | J11: 南天数据资产管理平台 | K11: 2024-07-30 | L11: iFinD ifind_get_stock_info (as of 2026-10-27)；南天数据资产管理平台 | M11: https://www.nantian.com.cn/case-detail/2375.html
B12: 002065 | C12: 东华软件 | D12: 数据要素_交易所 | E12: 重分类 | F12: 数据要素 | G12: 数据要素_数据治理 | H12: 相关 | I12: 年报列明大数据平台、数据交易所及金融数据资产管理平台建设；“替代数据通”整合公积金、社保、税务、司法和工商数据。主要是软件、集成和项目交付，不能据此认定为交易所运营方。 | J12: 东华软件2025年年度报告 | K12: 2026-04-10 | L12: iFinD ifind_get_stock_info (as of 2026-10-27)；东华软件2025年年度报告 | M12: http://static.cninfo.com.cn/finalpage/2026-04-10/1225090051.PDF
B13: 002095 | C13: 生意宝 | D13: 数据要素_大宗数据 | E13: 升级 | F13: 数据要素 | G13: 数据要素_大宗数据 | H13: 核心 | I13: 生意社持续加工大宗商品价格数据，形成多品种基准价，并通过期货通订阅及价格、指数API提供服务。数据来源、加工过程、产品形态和订阅或接口交付方式均明确，大宗数据是直接产品。 | J13: 生意社接口服务 | K13: 2019-02-22 | L13: iFinD ifind_get_stock_info (as of 2026-10-27)；生意社接口服务 | M13: https://www.100ppi.com/help/service/api.html
B14: 002152 | C14: 广电运通 | D14: 数据要素_数据存储 | E14: 重分类 | F14: 数据要素 | G14: 数据要素_数据运营 | H14: 相关 | I14: 运通信息、清远数投参与公共数据运营，“清易贷”“清易保”等产品已上架，中数智汇拥有产业链及ESG数据集。业务覆盖数据治理、产品开发和场景运营，但上市公司仍包含大量智能终端业务。 | J14: 广电运通公共数据运营业务说明 | K14: 2025-08-01 | L14: iFinD ifind_get_stock_info (as of 2026-10-27)；广电运通公共数据运营业务说明 | M14: https://www.grgbanking.com/cn/news/detail.html?id=2308
B15: 002153 | C15: 石基信息 | D15: 数据要素_酒店数据 | E15: 保留 | F15: 数据要素 | G15: 数据要素_酒店数据 | H15: 相关 | I15: DAYLIGHT PMS、Cambridge等系统处理酒店订单、餐饮和经营数据，并以SaaS订阅方式收费。公司持续处理行业数据，但主要销售酒店信息系统及订阅服务，而非独立数据库或数据产品。 | J15: 石基信息2024年年度报告摘要 | K15: 2025-04-29 | L15: iFinD ifind_get_stock_info (as of 2026-10-27)；石基信息2024年年度报告摘要 | M15: https://static.cninfo.com.cn/finalpage/2025-04-29/1223378885.PDF
... B81: 920207 | C81: 众诚科技 | D81: 数据要素_北交所 | E81: 重分类 | F81: 数据要素 | G81: 数据要素_数据清洗 | H81: 相关 | I81: 数据管理集成、数据资产管理及数据质量、ETL引擎处理政企数据，随软件开发和系统集成项目交付。业务实质是数据汇聚、清洗和质量治理，“北交所”仅表示上市地点，不能作为业务概念。 | J81: 众诚科技2025年年度报告 | K81: 2026-04-27 | L81: iFinD ifind_get_stock_info (as of 2026-10-27)；众诚科技2025年年度报告 | M81: https://money.finance.sina.com.cn/corp/view/vCB_AllBulletinDetail.php?stockid=920207&id=12229400

Sheet 摘除与迁出
B2: 摘除与迁出 · 审计清单
B3: 完全摘除 14 只；迁回物理 AI 7 只。历史标签仍保留在 watchlist 审计字段中。
B4: 代码 | C4: 名称 | D4: 旧概念 | E4: 动作 | F4: 新一级分类 | G4: 新概念 | H4: 判词 | I4: 详细理由 | J4: 证据名称 | K4: 证据日期 | L4: Source Name | M4: Source URL
B5: 000156 | C5: 华数传媒 | D5: 物理AI_数据采集 | E5: 摘除 | H5: 错标 | I5: 主业为有线电视、新媒体、宽带、智慧城市数字化及广电5G，收入来自节目传输、网络接入和数字化项目。数据要素仅是未来投资方向，未核到独立数据产品，更不属于物理AI数据采集。 | J5: 华数传媒2025年年度报告 | K5: 2026-03-21 | L5: iFinD ifind_get_stock_info (as of 2026-10-27)；华数传媒2025年年度报告 | M5: https://money.finance.sina.com.cn/corp/view/vCB_AllBulletinDetail.php?stockid=000156&id=12009319
B6: 000719 | C6: 中原传媒 | D6: 数据要素_交易所 | E6: 摘除 | H6: 边缘 | I6: 公司仅出资参股郑州数据交易中心，主营业务仍为出版、发行及相关文化服务。现有证据体现的是财务投资，而非上市公司直接建设或运营数据交易平台，严格口径下不参与数据要素选股。 | J6: 中原传媒参股郑州数据交易中心相关说明 | K6: 2024-11-18 | L6: iFinD ifind_get_stock_info (as of 2026-10-27)；中原传媒参股郑州数据交易中心相关说明 | M6: https://yuanchuang.10jqka.com.cn/20241118/c663606520.shtml
B7: 000810 | C7: 创维数字 | D7: 物理AI_数据采集 | E7: 迁出数据要素 | F7: 物理AI | G7: 物理AI_智能终端 | H7: 相关 | I7: 机顶盒、宽带连接终端、XR设备及摄像机属于智能终端硬件，现有主营资料未显示其对外提供数据采集、加工或数据集服务。应保留在物理AI终端链，而不是数据要素或数据采集概念。 | J7: 创维数字2025年年度报告摘要 | K7: 2026-03-28 | L7: iFinD ifind_get_stock_info (as of 2026-10-27)；创维数字2025年年度报告摘要 | M7: http://static.cninfo.com.cn/finalpage/2026-03-28/1225044554.PDF
B8: 002009 | C8: 天奇股份 | D8: 物理AI_数据采集 | E8: 迁出数据要素 | F8: 物理AI | G8: 物理AI_数据采集 | H8: 相关 | I8: 具身智能业务及实训中心采集多模态真机数据，用于机器人训练和交付验证，相关能力随装备、实训及解决方案项目落地。该标签适用于物理AI训练链，不应混入数据要素股池。 | J8: 天奇股份2025年年度报告摘要 | K8: 2026-04-28 | L8: iFinD ifind_get_stock_info (as of 2026-10-27)；天奇股份2025年年度报告摘要 | M8: https://static.cninfo.com.cn/finalpage/2026-04-28/1225218333.PDF
B9: 002076 | C9: 星光股份 | D9: 数据要素_其他行业数据 | E9: 摘除 | H9: 错标 | I9: 公司拟收购“造价通”事项已于2025年6月终止，相关合资公司亦未实缴，不能把造价通建材价格库计入上市公司。现有主营与独立行业数据产品之间缺少可核验的承接关系。 | J9: 星光股份终止收购相关公告及2025年半年度报告 | K9: 2025-08-30 | L9: iFinD ifind_get_stock_info (as of 2026-10-27)；星光股份终止收购相关公告及2025年半年度报告 | M9: https://money.finance.sina.com.cn/corp/view/vCB_AllBulletinDetail.php?stockid=002076&id=11423604
B10: 002354 | C10: 天娱数科 | D10: 物理AI_数据采集 | E10: 迁出数据要素 | F10: 物理AI | G10: 物理AI_数据采集 | H10: 相关 | I10: Behavision形成3D、多模态和机器人任务数据，并通过空间智能MaaS、数据集服务等方式交付，直接服务于机器人及物理AI训练。业务与物理AI相关，但不应与数据要素公共数据流通混为一组。 | J10: 天娱数科物理AI数据业务说明 | K10: 2025-07-28 | L10: iFinD ifind_get_stock_info (as of 2026-10-27)；天娱数科物理AI数据业务说明 | M10: https://www.tianyushuke.com/xwmt/2025/2025-07-28/907.html
B11: 002380 | C11: 科远智慧 | D11: 物理AI_数据采集 | E11: 迁出数据要素 | F11: 物理AI | G11: 物理AI_数据采集 | H11: 相关 | I11: NT6000 DCS、SyncBASE实时数据库和EmpoworX平台采集设备、工艺及质量数据，并随工控、MES、工业互联网项目交付。其采集对象主要是工业生产过程，适合物理AI工业数据链，不并入数据要素。 | J11: 科远智慧公司及产品体系介绍 | K11: 2018-08-08 | L11: iFinD ifind_get_stock_info (as of 2026-10-27)；科远智慧公司及产品体系介绍 | M11: https://www.sciyon.com/index.php/about/info.html
B12: 002869 | C12: 金溢科技 | D12: 数据要素_交通数据 | E12: 摘除 | H12: 边缘 | I12: OBU、RSU、RFID及全息路口采集车辆身份、收费和路况数据，主要以智能终端、路侧设备及边端系统项目销售。未核到独立交通数据产品收费，属于上游感知和项目交付，严格口径下移出数据要素。 | J12: 金溢科技2024年年度报告 | K12: 2025-04-22 | L12: iFinD ifind_get_stock_info (as of 2026-10-27)；金溢科技2024年年度报告 | M12: http://money.finance.sina.com.cn/corp/view/vCB_AllBulletinDetail.php?stockid=002869&id=10921058
B13: 300085 | C13: 银之杰 | D13: 数据要素_其他行业数据 | E13: 摘除 | H13: 边缘 | I13: 金融软件、数据中台为银行处理业务数据并按软件和设备交付，征信逻辑主要来自联营及参股机构。上市公司自身未见独立征信数据主产品，且其他业务占比较大，严格口径下不再纳入数据要素。 | J13: 银之杰2025年年度报告 | K13: 2026-04-15 | L13: iFinD ifind_get_stock_info (as of 2026-10-27)；银之杰2025年年度报告 | M13: https://money.finance.sina.com.cn/corp/view/vCB_AllBulletinDetail.php?stockid=300085&id=12089901
B14: 300552 | C14: 万集科技 | D14: 数据要素_交通数据 | E14: 摘除 | H14: 边缘 | I14: ETC、激光雷达、动态称重和V2X路侧设备采集车辆重量、轮廓、轨迹及路况数据，收入来自智能交通设备和系统项目。未核到独立交通数据产品收费，属于上游感知端。 | J14: 万集科技2025年年度报告 | K14: 2026-03-31 | L14: iFinD ifind_get_stock_info (as of 2026-10-27)；万集科技2025年年度报告 | M14: https://wanji.net.cn/uploadfile/2026/0331/20260331013334898.pdf
B15: 300949 | C15: 奥雅股份 | D15: 数据要素_其他行业数据 | E15: 摘除 | H15: 错标 | I15: 灵绘、奥创和植物数据库把植物、空间指标用于内部景观生成与文旅设计提效，收入仍来自景观设计和综合文旅项目。未见对外销售数据库、数据订阅或授权运营产品，数字科技不等于数据要素。 | J15: 奥雅股份2025年年度报告 | K15: 2026-04-29 | L15: iFinD ifind_get_stock_info (as of 2026-10-27)；奥雅股份2025年年度报告 | M15: https://money.finance.sina.com.cn/corp/view/vCB_AllBulletinDetail.php?stockid=300949&id=12255135
B16: 301215 | C16: 中汽股份 | D16: 数据要素_汽车数据 | E16: 摘除 | H16: 边缘 | I16: 试验场在整车、轮胎及智能网联测试中形成车速、工况和性能数据，但客户购买的是场地及配套试验技术服务，按道路时长、里程或包场结算。测试数据服务于报告交付，未核到独立数据库销售。 | J16: 中汽股份2025年年度报告 | K16: 2026-04-29 | L16: iFinD ifind_get_stock_info (as of 2026-10-27)；中汽股份2025年年度报告 | M16: https://static.cninfo.com.cn/finalpage/2026-04-29/1225242619.PDF
B17: 301231 | C17: 荣信文化 | D17: 数据要素_内容数据 | E17: 摘除 | H17: 错标 | I17: 核心产品是立体书、翻翻书等少儿图书，通过策划、版权授权、印刷和发行实现销售。未核到将图书内容加工为数据库、语料包或数据接口并单独授权收费，出版版权不能直接等同内容数据产品。 | J17: 荣信文化2025年半年度报告 | K17: 2025-08-28 | L17: iFinD ifind_get_stock_info (as of 2026-10-27)；荣信文化2025年半年度报告 | M17: http://static.cninfo.com.cn/finalpage/2025-08-28/1224600002.PDF
B18: 301428 | C18: 世纪恒通 | D18: 数据要素_营销数据 | E18: 摘除 | H18: 边缘 | I18: 车后服务平台接入商户API，处理车主、优惠券、会员权益和营销触达数据，用于权益运营、客服及营销推广。按企业服务采购和运营项目收费，数据主要支撑自有服务，未核到独立营销数据库产品。 | J18: 世纪恒通2024年年度报告摘要 | K18: 2025-04-26 | L18: iFinD ifind_get_stock_info (as of 2026-10-27)；世纪恒通2024年年度报告摘要 | M18: https://static.cninfo.com.cn/finalpage/2025-04-26/1223313183.PDF
B19: 600604 | C19: 市北高新 | D19: 数据要素_交易所 | E19: 摘除 | H19: 边缘 | I19: 上市公司收入来自园区载体销售、住宅、租赁和园区服务；旧概念依据为持有上海数据交易中心少量股权，未见其负责交易所运营或按数据交易收费。少量参股只形成间接敞口。 | J19: 市北高新2024年年度报告 | K19: 2025-04-12 | L19: iFinD ifind_get_stock_info (as of 2026-10-27)；市北高新2024年年度报告 | M19: https://static.cninfo.com.cn/finalpage/2025-04-12/1223069636.PDF
B20: 600822 | C20: 上海物贸 | D20: 数据要素_其他行业数据 | E20: 摘除 | H20: 错标 | I20: 子公司上海有色金属交易中心曾将“有色金属现货指数查询”挂牌数据交易所，但公司风险公告明确该产品挂牌后未成交且目前暂失效，未贡献经营业绩；当前主业仍为金属和汽车贸易。 | J20: 上海物贸股票交易风险提示公告 | K20: 2025-07-17 | L20: iFinD ifind_get_stock_info (as of 2026-10-27)；上海物贸股票交易风险提示公告 | M20: https://data.eastmoney.com/notices/detail/600822/AN202507171710657701.html
B21: 601999 | C21: 出版传媒 | D21: 数据要素_内容数据 | E21: 摘除 | H21: 错标 | I21: 主要经营一般图书、教材教辅、纸张印刷物资和票据印刷，通过图书包销、经销及物资销售交付。未见独立数据库、内容数据接口或语料授权收费产品，不能将出版资源直接认定为内容数据业务。 | J21: 出版传媒2024年年度报告 | K21: 2025-04-10 | L21: iFinD ifind_get_stock_info (as of 2026-10-27)；出版传媒2024年年度报告 | M21: https://vip.stock.finance.sina.com.cn/corp/view/vCB_AllBulletinDetail.php?stockid=601999&id=10859582
B22: 603341 | C22: 龙旗科技 | D22: 物理AI_数据采集 | E22: 迁出数据要素 | F22: 物理AI | G22: 物理AI_智能终端 | H22: 相关 | I22: 公司按ODM模式研发、制造并销售智能手机、平板和AIoT整机，收入来自终端产品交付。终端运行虽会产生数据，但未核到面向客户的数据采集、治理或授权产品，应迁回物理AI终端链。 | J22: 龙旗科技2025年年度报告 | K22: 2026-03-30 | L22: iFinD ifind_get_stock_info (as of 2026-10-27)；龙旗科技2025年年度报告 | M22: https://www.hkexnews.hk/listedco/listconews/sehk/2026/0330/2026033004243_c.pdf
B23: 603466 | C23: 风语筑 | D23: 物理AI_数据采集 | E23: 摘除 | H23: 错标 | I23: 城市、文化及品牌体验空间按策划、设计、实施和维护项目收费，沉浸交互与AI视频用于展示内容。项目重点是空间体验和展陈工程，未核到独立数据采集产品、数据交付或授权收费。 | J23: 风语筑2025年半年度报告 | K23: 2025-08-29 | L23: iFinD ifind_get_stock_info (as of 2026-10-27)；风语筑2025年半年度报告 | M23: http://static.cninfo.com.cn/finalpage/2025-08-29/1224603815.PDF
B24: 605488 | C24: 福莱新材 | D24: 物理AI_数据采集 | E24: 迁出数据要素 | F24: 物理AI | G24: 物理AI_传感器 | H24: 相关 | I24: 欧仁新材料、柔感未来等电子皮肤感知压力和剪切力，产品以柔性传感器硬件及方案销售交付，服务机器人触觉感知。其属于物理AI上游传感器，不是数据要素产品或数据运营。 | J24: 福莱新材2025年年度报告 | K24: 2026-04-28 | L24: iFinD ifind_get_stock_info (as of 2026-10-27)；福莱新材2025年年度报告 | M24: http://money.finance.sina.com.cn/corp/view/vCB_AllBulletinDetail.php?stockid=605488&id=12210056
B25: 688686 | C25: 奥普特 | D25: 物理AI_数据采集 | E25: 迁出数据要素 | F25: 物理AI | G25: 物理AI_机器视觉 | H25: 相关 | I25: 相机、光源、镜头及视觉算法采集工业图像用于检测识别，按机器视觉核心部件和解决方案销售。图像采集服务于工业检测设备，属于物理AI感知上游，未形成数据要素产品或数据运营。 | J25: 奥普特2025年年度报告 | K25: 2026-04-03 | L25: iFinD ifind_get_stock_info (as of 2026-10-27)；奥普特2025年年度报告 | M25: https://vip.stock.finance.sina.com.cn/corp/view/vCB_AllBulletinDetail.php?stockid=688686&id=12060637

Sheet 数据存储复核
B2: 数据存储 · 截图原15只专项复核
B3: 重点纠正把数据库、数据治理、数据运营和IDC全部混入“数据存储”的旧口径。
B4: 代码 | C4: 名称 | D4: 旧概念 | E4: 动作 | F4: 新一级分类 | G4: 新概念 | H4: 判词 | I4: 详细理由 | J4: 证据名称 | K4: 证据日期 | L4: Source Name | M4: Source URL
B5: 002368 | C5: 太极股份 | D5: 数据要素_数据存储 | E5: 重分类 | F5: 数据要素 | G5: 数据要素_数据库 | H5: 相关 | I5: 电科金仓KingbaseES、KES及分布式HTAP数据库通过许可、一体机和项目方式交付，承担数据组织、查询、事务处理和管理功能。产品层级是数据库软件，不等同于通用存储设备。 | J5: 太极股份2024年年度报告 | K5: 2025-04-02 | L5: iFinD ifind_get_stock_info (as of 2026-10-27)；太极股份2024年年度报告 | M5: https://money.finance.sina.com.cn/corp/view/vCB_AllBulletinDetail.php?stockid=002368&id=10840405
B6: 601728 | C6: 中国电信 | D6: 数据要素_数据存储 | E6: 保留 | F6: 数据要素 | G6: 数据要素_数据存储 | H6: 相关 | I6: 天翼云和IDC为政企客户提供云资源、机柜、存储及产业数字化服务，按资源使用和项目服务收费。数据存储属于明确业务板块，但集团主要仍是通信及云网基础设施。 | J6: 中国电信2024年年度报告 | K6: 2025-03-25 | L6: iFinD ifind_get_stock_info (as of 2026-10-27)；中国电信2024年年度报告 | M6: https://www.chinatelecom-h.com/sc/ir/report/annual2024_ashare.pdf
B7: 000948 | C7: 南天信息 | D7: 数据要素_数据存储 | E7: 重分类 | F7: 数据要素 | G7: 数据要素_数据治理 | H7: 相关 | I7: 南天数据资产管理平台覆盖数据集成、治理、目录、盘点和运营，主要面向金融客户以IT项目方式交付。其价值在于把分散数据加工为可管理、可使用的资产，而非提供底层存储介质。 | J7: 南天数据资产管理平台 | K7: 2024-07-30 | L7: iFinD ifind_get_stock_info (as of 2026-10-27)；南天数据资产管理平台 | M7: https://www.nantian.com.cn/case-detail/2375.html
B8: 603138 | C8: 海量数据 | D8: 数据要素_数据存储 | E8: 重分类 | F8: 数据要素 | G8: 数据要素_数据库 | H8: 核心 | I8: Vastbase G100、V100、M100是明确数据库主产品，处理关系、向量等数据，以软件使用许可销售并配套迁移、运维服务。交付标的即数据库软件及持续服务，应与基础设施型数据存储区分。 | J8: 海量数据2025年年度报告 | K8: 2026-04-17 | L8: iFinD ifind_get_stock_info (as of 2026-10-27)；海量数据2025年年度报告 | M8: http://file.finance.sina.com.cn/211.154.219.97:9494/MRGG/CNSESH_STOCK/2026/2026-4/2026-04-17/12102825.PDF
B9: 600050 | C9: 中国联通 | D9: 数据要素_数据存储 | E9: 保留 | F9: 数据要素 | G9: 数据要素_数据存储 | H9: 相关 | I9: 联通云和数据中心面向政企提供云网、机柜、存储及算力资源，按通信、云资源和数据中心服务收费。虽另有政务数据平台及可信数据空间，集团主要交付仍是连接和算网基础设施。 | J9: 中国联通2024年年度报告摘要 | K9: 2025-03-18 | L9: iFinD ifind_get_stock_info (as of 2026-10-27)；中国联通2024年年度报告摘要 | M9: http://file.finance.sina.com.cn/211.154.219.97:9494/MRGG/CNSESH_STOCK/2025/2025-3/2025-03-19/10790569.PDF
B10: 600941 | C10: 中国移动 | D10: 数据要素_数据存储 | E10: 保留 | F10: 数据要素 | G10: 数据要素_数据存储 | H10: 相关 | I10: 移动云和数据中心、AIDC提供云存储、机柜及算网服务，按云资源和政企项目收费。梧桐大数据等能力不能改变集团以通信连接和基础设施为主的交付结构，因此不列为核心数据产品商。 | J10: 中国移动2024年业绩及数字化转型说明 | K10: 2025-03-20 | L10: iFinD ifind_get_stock_info (as of 2026-10-27)；中国移动2024年业绩及数字化转型说明 | M10: https://www.10086.cn/aboutus/news/groupnews/index_detail_52089.html
B11: 000032 | C11: 深桑达A | D11: 数据要素_数据存储 | E11: 重分类 | F11: 数据要素 | G11: 数据要素_数据运营 | H11: 核心 | I11: 中国电子云数据港对接获授权的公共数据与社会数据，开展治理、融合和产品孵化，并以“蚝保宝”等数据产品面向企业及交易所输出。业务重点是持续运营和数据产品服务，而非单纯提供存储资源。 | J11: 深桑达A 2024年年度报告摘要 | K11: 2025-04-25 | L11: iFinD ifind_get_stock_info (as of 2026-10-27)；深桑达A 2024年年度报告摘要 | M11: https://static.cninfo.com.cn/finalpage/2025-04-25/1223281534.PDF
B12: 000158 | C12: 常山北明 | D12: 数据要素_数据存储 | E12: 重分类 | F12: 数据要素 | G12: 数据要素_数据治理 | H12: 相关 | I12: 北明软件具备数据资源化、产品化、资产化、资本化流程服务，配有数据资产管理平台，并在交通、港口及企业场景开展统一治理。收入仍主要来自系统集成、行业解决方案和定制软件，不属于底层存储产品。 | J12: 常山北明2025年年度报告 | K12: 2026-04-03 | L12: iFinD ifind_get_stock_info (as of 2026-10-27)；常山北明2025年年度报告 | M12: http://money.finance.sina.com.cn/corp/view/vCB_AllBulletinDetail.php?stockid=000158&id=12060253
B13: 000815 | C13: 美利云 | D13: 数据要素_数据存储 | E13: 升级 | F13: 数据要素 | G13: 数据要素_数据存储 | H13: 相关 | I13: 公司已于2024年底停止造纸，旧“造纸为主”理由失效；誉成云创目前提供机架、网络接入及运维并按合同收费，云业务已成为主体。其本质仍是IDC基础设施服务，而非数据内容运营，故列相关而非核心。 | J13: 美利云2025年年度报告 | K13: 2026-04-24 | L13: iFinD ifind_get_stock_info (as of 2026-10-27)；美利云2025年年度报告 | M13: http://static.cninfo.com.cn/finalpage/2026-04-24/1225160605.PDF
B14: 000938 | C14: 紫光股份 | D14: 数据要素_数据存储 | E14: 保留 | F14: 数据要素 | G14: 数据要素_数据存储 | H14: 相关 | I14: 新华三ONEStor、UniStor等产品处理块、文件、对象及非结构化数据，通过软硬件、软件授权和解决方案交付。产品确属数据存储基础设施，但上市公司业务还覆盖网络、计算及云服务，因此维持相关。 | J14: H3C ONEStor分布式存储软件 | K14: 无日期 | L14: iFinD ifind_get_stock_info (as of 2026-10-27)；H3C ONEStor分布式存储软件 | M14: https://www.h3c.com/cn/Products_And_Solution/Storage/H3C/Products/Mass_Storage_Device/Products_Series/Software/ONEStor_5.0/
B15: 300895 | C15: 铜牛信息 | D15: 数据要素_数据存储 | E15: 保留 | F15: 数据要素 | G15: 数据要素_数据存储 | H15: 相关 | I15: 自建IDC和云平台为客户托管服务器，提供带宽、备份、恢复和日志分析，按资源、托管及系统集成收费。公司承载客户数据而不生产或运营自有数据内容，属于数据存储基础设施。 | J15: 铜牛信息2025年年度报告 | K15: 2026-04-23 | L15: iFinD ifind_get_stock_info (as of 2026-10-27)；铜牛信息2025年年度报告 | M15: https://money.finance.sina.com.cn/corp/view/vCB_AllBulletinDetail.php?stockid=300895&id=12153341
... B19: 600037 | C19: 歌华有线 | D19: 数据要素_数据存储 | E19: 保留 | F19: 数据要素 | G19: 数据要素_数据存储 | H19: 相关 | I19: 主营仍为北京地区有线电视网络，同时建设“歌华云”混合云并具备IaaS、PaaS、SaaS能力，为集团客户提供云和数据业务服务。按云资源及项目服务收费，属于存储基础设施。 | J19: 歌华有线2024年年度报告 | K19: 2025-04-25 | L19: iFinD ifind_get_stock_info (as of 2026-10-27)；歌华有线2024年年度报告 | M19: http://money.finance.sina.com.cn/corp/view/vCB_AllBulletinDetail.php?stockid=600037&id=10962081

Sheet 概念统计
B2: 保留股池 · 二级概念分布
B3: 统计范围仅为清洗后保留的77只；数量由公式引用“保留股池”计算。
B4: 二级概念 | C4: 核心（只） | D4: 相关（只） | E4: 合计（只）
B5: 数据要素_交易所 | C5: =COUNTIFS('保留股池'!$G$5:$G$81,B5,'保留股池'!$H$5:$H$81,"核心") | D5: =COUNTIFS('保留股池'!$G$5:$G$81,B5,'保留股池'!$H$5:$H$81,"相关") | E5: =SUM(C5:D5)
B6: 数据要素_交通数据 | C6: =COUNTIFS('保留股池'!$G$5:$G$81,B6,'保留股池'!$H$5:$H$81,"核心") | D6: =COUNTIFS('保留股池'!$G$5:$G$81,B6,'保留股池'!$H$5:$H$81,"相关") | E6: =SUM(C6:D6)
B7: 数据要素_其他行业数据 | C7: =COUNTIFS('保留股池'!$G$5:$G$81,B7,'保留股池'!$H$5:$H$81,"核心") | D7: =COUNTIFS('保留股池'!$G$5:$G$81,B7,'保留股池'!$H$5:$H$81,"相关") | E7: =SUM(C7:D7)
B8: 数据要素_内容数据 | C8: =COUNTIFS('保留股池'!$G$5:$G$81,B8,'保留股池'!$H$5:$H$81,"核心") | D8: =COUNTIFS('保留股池'!$G$5:$G$81,B8,'保留股池'!$H$5:$H$81,"相关") | E8: =SUM(C8:D8)
B9: 数据要素_医疗数据 | C9: =COUNTIFS('保留股池'!$G$5:$G$81,B9,'保留股池'!$H$5:$H$81,"核心") | D9: =COUNTIFS('保留股池'!$G$5:$G$81,B9,'保留股池'!$H$5:$H$81,"相关") | E9: =SUM(C9:D9)
B10: 数据要素_司法数据 | C10: =COUNTIFS('保留股池'!$G$5:$G$81,B10,'保留股池'!$H$5:$H$81,"核心") | D10: =COUNTIFS('保留股池'!$G$5:$G$81,B10,'保留股池'!$H$5:$H$81,"相关") | E10: =SUM(C10:D10)
B11: 数据要素_图片数据 | C11: =COUNTIFS('保留股池'!$G$5:$G$81,B11,'保留股池'!$H$5:$H$81,"核心") | D11: =COUNTIFS('保留股池'!$G$5:$G$81,B11,'保留股池'!$H$5:$H$81,"相关") | E11: =SUM(C11:D11)
B12: 数据要素_大宗数据 | C12: =COUNTIFS('保留股池'!$G$5:$G$81,B12,'保留股池'!$H$5:$H$81,"核心") | D12: =COUNTIFS('保留股池'!$G$5:$G$81,B12,'保留股池'!$H$5:$H$81,"相关") | E12: =SUM(C12:D12)
B13: 数据要素_学术数据 | C13: =COUNTIFS('保留股池'!$G$5:$G$81,B13,'保留股池'!$H$5:$H$81,"核心") | D13: =COUNTIFS('保留股池'!$G$5:$G$81,B13,'保留股池'!$H$5:$H$81,"相关") | E13: =SUM(C13:D13)
B14: 数据要素_教育数据 | C14: =COUNTIFS('保留股池'!$G$5:$G$81,B14,'保留股池'!$H$5:$H$81,"核心") | D14: =COUNTIFS('保留股池'!$G$5:$G$81,B14,'保留股池'!$H$5:$H$81,"相关") | E14: =SUM(C14:D14)
B15: 数据要素_数据分析 | C15: =COUNTIFS('保留股池'!$G$5:$G$81,B15,'保留股池'!$H$5:$H$81,"核心") | D15: =COUNTIFS('保留股池'!$G$5:$G$81,B15,'保留股池'!$H$5:$H$81,"相关") | E15: =SUM(C15:D15)
B16: 数据要素_数据存储 | C16: =COUNTIFS('保留股池'!$G$5:$G$81,B16,'保留股池'!$H$5:$H$81,"核心") | D16: =COUNTIFS('保留股池'!$G$5:$G$81,B16,'保留股池'!$H$5:$H$81,"相关") | E16: =SUM(C16:D16)
... B29: 数据要素_酒店数据 | C29: =COUNTIFS('保留股池'!$G$5:$G$81,B29,'保留股池'!$H$5:$H$81,"核心") | D29: =COUNTIFS('保留股池'!$G$5:$G$81,B29,'保留股池'!$H$5:$H$81,"相关") | E29: =SUM(C29:D29)
B30: 合计 | C30: =SUM(C5:C29) | D30: =SUM(D5:D29) | E30: =SUM(E5:E29)
